Watching for file changes with StatReloader
/home/sarw/Programming/xcounter/xcounter/settings.py changed, reloading.
Performing system checks...

System check identified no issues (0 silenced).
May 11, 2025 - 01:12:30
Django version 5.2.1, using settings 'xcounter.settings'
Starting development server at http://127.0.0.1:8000/
Quit the server with CONTROL-C.

WARNING: This is a development server. Do not use it in a production setting. Use a production WSGI or ASGI server instead.
For more information on production servers see: https://docs.djangoproject.com/en/5.2/howto/deployment/
Watching for file changes with StatReloader
Exception in thread django-main-thread:
Traceback (most recent call last):
  File "/home/sarw/.nix-profile/lib/python3.12/threading.py", line 1075, in _bootstrap_inner
    self.run()
  File "/home/sarw/.nix-profile/lib/python3.12/threading.py", line 1012, in run
    self._target(*self._args, **self._kwargs)
  File "/home/sarw/Programming/xcounter/venv/lib/python3.12/site-packages/django/utils/autoreload.py", line 64, in wrapper
    fn(*args, **kwargs)
  File "/home/sarw/Programming/xcounter/venv/lib/python3.12/site-packages/django/core/management/commands/runserver.py", line 134, in inner_run
    self.check(**check_kwargs)
  File "/home/sarw/Programming/xcounter/venv/lib/python3.12/site-packages/django/core/management/base.py", line 492, in check
    all_issues = checks.run_checks(
                 ^^^^^^^^^^^^^^^^^^
  File "/home/sarw/Programming/xcounter/venv/lib/python3.12/site-packages/django/core/checks/registry.py", line 89, in run_checks
    new_errors = check(app_configs=app_configs, databases=databases)
                 ^^^^^^^^^^^^^^^^^^^^^^^^^^^^^^^^^^^^^^^^^^^^^^^^^^^
  File "/home/sarw/Programming/xcounter/venv/lib/python3.12/site-packages/django/core/checks/urls.py", line 16, in check_url_config
    return check_resolver(resolver)
           ^^^^^^^^^^^^^^^^^^^^^^^^
  File "/home/sarw/Programming/xcounter/venv/lib/python3.12/site-packages/django/core/checks/urls.py", line 26, in check_resolver
    return check_method()
           ^^^^^^^^^^^^^^
  File "/home/sarw/Programming/xcounter/venv/lib/python3.12/site-packages/django/urls/resolvers.py", line 531, in check
    for pattern in self.url_patterns:
                   ^^^^^^^^^^^^^^^^^
  File "/home/sarw/Programming/xcounter/venv/lib/python3.12/site-packages/django/utils/functional.py", line 47, in __get__
    res = instance.__dict__[self.name] = self.func(instance)
                                         ^^^^^^^^^^^^^^^^^^^
  File "/home/sarw/Programming/xcounter/venv/lib/python3.12/site-packages/django/urls/resolvers.py", line 718, in url_patterns
    patterns = getattr(self.urlconf_module, "urlpatterns", self.urlconf_module)
                       ^^^^^^^^^^^^^^^^^^^
  File "/home/sarw/Programming/xcounter/venv/lib/python3.12/site-packages/django/utils/functional.py", line 47, in __get__
    res = instance.__dict__[self.name] = self.func(instance)
                                         ^^^^^^^^^^^^^^^^^^^
  File "/home/sarw/Programming/xcounter/venv/lib/python3.12/site-packages/django/urls/resolvers.py", line 711, in urlconf_module
    return import_module(self.urlconf_name)
           ^^^^^^^^^^^^^^^^^^^^^^^^^^^^^^^^
  File "/home/sarw/.nix-profile/lib/python3.12/importlib/__init__.py", line 90, in import_module
    return _bootstrap._gcd_import(name[level:], package, level)
           ^^^^^^^^^^^^^^^^^^^^^^^^^^^^^^^^^^^^^^^^^^^^^^^^^^^^
  File "<frozen importlib._bootstrap>", line 1387, in _gcd_import
  File "<frozen importlib._bootstrap>", line 1360, in _find_and_load
  File "<frozen importlib._bootstrap>", line 1331, in _find_and_load_unlocked
  File "<frozen importlib._bootstrap>", line 935, in _load_unlocked
  File "<frozen importlib._bootstrap_external>", line 999, in exec_module
  File "<frozen importlib._bootstrap>", line 488, in _call_with_frames_removed
  File "/home/sarw/Programming/xcounter/xcounter/urls.py", line 77, in <module>
    path("api/reviews/", include("reviews.urls")),
                         ^^^^^^^^^^^^^^^^^^^^^^^
  File "/home/sarw/Programming/xcounter/venv/lib/python3.12/site-packages/django/urls/conf.py", line 39, in include
    urlconf_module = import_module(urlconf_module)
                     ^^^^^^^^^^^^^^^^^^^^^^^^^^^^^
  File "/home/sarw/.nix-profile/lib/python3.12/importlib/__init__.py", line 90, in import_module
    return _bootstrap._gcd_import(name[level:], package, level)
           ^^^^^^^^^^^^^^^^^^^^^^^^^^^^^^^^^^^^^^^^^^^^^^^^^^^^
  File "<frozen importlib._bootstrap>", line 1387, in _gcd_import
  File "<frozen importlib._bootstrap>", line 1360, in _find_and_load
  File "<frozen importlib._bootstrap>", line 1331, in _find_and_load_unlocked
  File "<frozen importlib._bootstrap>", line 935, in _load_unlocked
  File "<frozen importlib._bootstrap_external>", line 999, in exec_module
  File "<frozen importlib._bootstrap>", line 488, in _call_with_frames_removed
  File "/home/sarw/Programming/xcounter/reviews/urls.py", line 5, in <module>
    from . import views
  File "/home/sarw/Programming/xcounter/reviews/views.py", line 8, in <module>
    from .models import Review, ReviewReply
  File "/home/sarw/Programming/xcounter/reviews/models.py", line 8, in <module>
    class Review(models.Model):
  File "/home/sarw/Programming/xcounter/venv/lib/python3.12/site-packages/django/db/models/base.py", line 136, in __new__
    raise RuntimeError(
RuntimeError: Model class reviews.models.Review doesn't declare an explicit app_label and isn't in an application in INSTALLED_APPS.
/home/sarw/Programming/xcounter/movies/models.py changed, reloading.
Performing system checks...

Watching for file changes with StatReloader
